Workbook

Sheet Summary
A1: Google Trends Keyword List: Fashion Trend Forecasting
A2: Keywords are English, grouped by category. Batches use 4 keywords plus 1 shared anchor term (Google Trends compares at most 5 terms).
A4: Anchor term (edit) | B4: leggings | C4: Placeholder. Test 2-3 candidates (e.g. leggings, blazer, handbag); pick one with no zero weeks, no strong trend or seasonality, and a scale close to your keywords. Changing this cell updates the Batches sheet.
A6: Category | B6: Keywords | C6: Medium ambiguity risk | D6: Pulled | E6: Kept
A7: Jeans and denim | B7: =COUNTIF(Keywords!$C$2:$C$138,A7) -> 14 | C7: =COUNTIFS(Keywords!$C$2:$C$138,A7,Keywords!$E$2:$E$138,"Medium") -> 0 | D7: =COUNTIFS(Keywords!$C$2:$C$138,A7,Keywords!$G$2:$G$138,"Yes") -> 0 | E7: =COUNTIFS(Keywords!$C$2:$C$138,A7,Keywords!$I$2:$I$138,"Yes") -> 0
A8: Trousers and shorts | B8: =COUNTIF(Keywords!$C$2:$C$138,A8) -> 15 | C8: =COUNTIFS(Keywords!$C$2:$C$138,A8,Keywords!$E$2:$E$138,"Medium") -> 0 | D8: =COUNTIFS(Keywords!$C$2:$C$138,A8,Keywords!$G$2:$G$138,"Yes") -> 0 | E8: =COUNTIFS(Keywords!$C$2:$C$138,A8,Keywords!$I$2:$I$138,"Yes") -> 0
A9: Skirts and dresses | B9: =COUNTIF(Keywords!$C$2:$C$138,A9) -> 12 | C9: =COUNTIFS(Keywords!$C$2:$C$138,A9,Keywords!$E$2:$E$138,"Medium") -> 0 | D9: =COUNTIFS(Keywords!$C$2:$C$138,A9,Keywords!$G$2:$G$138,"Yes") -> 0 | E9: =COUNTIFS(Keywords!$C$2:$C$138,A9,Keywords!$I$2:$I$138,"Yes") -> 0
A10: Tops and knitwear | B10: =COUNTIF(Keywords!$C$2:$C$138,A10) -> 14 | C10: =COUNTIFS(Keywords!$C$2:$C$138,A10,Keywords!$E$2:$E$138,"Medium") -> 0 | D10: =COUNTIFS(Keywords!$C$2:$C$138,A10,Keywords!$G$2:$G$138,"Yes") -> 0 | E10: =COUNTIFS(Keywords!$C$2:$C$138,A10,Keywords!$I$2:$I$138,"Yes") -> 0
A11: Outerwear | B11: =COUNTIF(Keywords!$C$2:$C$138,A11) -> 10 | C11: =COUNTIFS(Keywords!$C$2:$C$138,A11,Keywords!$E$2:$E$138,"Medium") -> 0 | D11: =COUNTIFS(Keywords!$C$2:$C$138,A11,Keywords!$G$2:$G$138,"Yes") -> 0 | E11: =COUNTIFS(Keywords!$C$2:$C$138,A11,Keywords!$I$2:$I$138,"Yes") -> 0
A12: Shoes | B12: =COUNTIF(Keywords!$C$2:$C$138,A12) -> 14 | C12: =COUNTIFS(Keywords!$C$2:$C$138,A12,Keywords!$E$2:$E$138,"Medium") -> 2 | D12: =COUNTIFS(Keywords!$C$2:$C$138,A12,Keywords!$G$2:$G$138,"Yes") -> 0 | E12: =COUNTIFS(Keywords!$C$2:$C$138,A12,Keywords!$I$2:$I$138,"Yes") -> 0
A13: Bags | B13: =COUNTIF(Keywords!$C$2:$C$138,A13) -> 10 | C13: =COUNTIFS(Keywords!$C$2:$C$138,A13,Keywords!$E$2:$E$138,"Medium") -> 2 | D13: =COUNTIFS(Keywords!$C$2:$C$138,A13,Keywords!$G$2:$G$138,"Yes") -> 0 | E13: =COUNTIFS(Keywords!$C$2:$C$138,A13,Keywords!$I$2:$I$138,"Yes") -> 0
A14: Accessories | B14: =COUNTIF(Keywords!$C$2:$C$138,A14) -> 12 | C14: =COUNTIFS(Keywords!$C$2:$C$138,A14,Keywords!$E$2:$E$138,"Medium") -> 0 | D14: =COUNTIFS(Keywords!$C$2:$C$138,A14,Keywords!$G$2:$G$138,"Yes") -> 0 | E14: =COUNTIFS(Keywords!$C$2:$C$138,A14,Keywords!$I$2:$I$138,"Yes") -> 0
A15: Patterns and materials | B15: =COUNTIF(Keywords!$C$2:$C$138,A15) -> 11 | C15: =COUNTIFS(Keywords!$C$2:$C$138,A15,Keywords!$E$2:$E$138,"Medium") -> 5 | D15: =COUNTIFS(Keywords!$C$2:$C$138,A15,Keywords!$G$2:$G$138,"Yes") -> 0 | E15: =COUNTIFS(Keywords!$C$2:$C$138,A15,Keywords!$I$2:$I$138,"Yes") -> 0
A16: Colors | B16: =COUNTIF(Keywords!$C$2:$C$138,A16) -> 8 | C16: =COUNTIFS(Keywords!$C$2:$C$138,A16,Keywords!$E$2:$E$138,"Medium") -> 8 | D16: =COUNTIFS(Keywords!$C$2:$C$138,A16,Keywords!$G$2:$G$138,"Yes") -> 0 | E16: =COUNTIFS(Keywords!$C$2:$C$138,A16,Keywords!$I$2:$I$138,"Yes") -> 0
A17: Aesthetics and styles | B17: =COUNTIF(Keywords!$C$2:$C$138,A17) -> 17 | C17: =COUNTIFS(Keywords!$C$2:$C$138,A17,Keywords!$E$2:$E$138,"Medium") -> 1 | D17: =COUNTIFS(Keywords!$C$2:$C$138,A17,Keywords!$G$2:$G$138,"Yes") -> 0 | E17: =COUNTIFS(Keywords!$C$2:$C$138,A17,Keywords!$I$2:$I$138,"Yes") -> 0
A18: Total | B18: =SUM(B7:B17) -> 137 | C18: =SUM(C7:C17) -> 18 | D18: =SUM(D7:D17) -> 0 | E18: =SUM(E7:E17) -> 0
A19: Batches needed | B19: =ROUNDUP(B18/4,0) -> 35
A21: How to use
A22: 1. Yellow cells are for you to fill. Keywords sheet: Pulled? (Yes/No), Zero share (e.g. 0.12 means 12% of weeks are zero), Keep? (Yes/No).
A23: 2. Pull each batch from the Batches sheet (paste the query string into Google Trends) with the same region, language and date range every time.
A24: 3. Check keywords marked Medium in the Keywords sheet by looking at related queries; reword or drop them if they are not about fashion.
A25: 4. Over-collect now; set the zero-share cut-off after EDA and drop low-volume keywords then.
A26: 5. Brand names are left out on purpose, since they mostly reflect brand demand and not a style trend.
A27: 6. Optional: Google Trends has a Shopping > Apparel category filter to cut ambiguity (believed to be category 68; verify in the UI).
A28: 7. Source: keyword list compiled by Claude as a starting point for this project; not validated against Google Trends volumes yet.

Sheet Keywords
A1: # | B1: Keyword | C1: Category | D1: Batch # | E1: Ambiguity risk | F1: Check note | G1: Pulled? (Yes/No) | H1: Zero share (0-1) | I1: Keep? (Yes/No)
A2: 1 | B2: skinny jeans | C2: Jeans and denim | D2: =INT((A2-1)/4)+1 -> 1 | E2: Low
A3: 2 | B3: wide leg jeans | C3: Jeans and denim | D3: =INT((A3-1)/4)+1 -> 1 | E3: Low
A4: 3 | B4: baggy jeans | C4: Jeans and denim | D4: =INT((A4-1)/4)+1 -> 1 | E4: Low
A5: 4 | B5: straight leg jeans | C5: Jeans and denim | D5: =INT((A5-1)/4)+1 -> 1 | E5: Low
A6: 5 | B6: bootcut jeans | C6: Jeans and denim | D6: =INT((A6-1)/4)+1 -> 2 | E6: Low
A7: 6 | B7: flare jeans | C7: Jeans and denim | D7: =INT((A7-1)/4)+1 -> 2 | E7: Low
A8: 7 | B8: mom jeans | C8: Jeans and denim | D8: =INT((A8-1)/4)+1 -> 2 | E8: Low
A9: 8 | B9: low rise jeans | C9: Jeans and denim | D9: =INT((A9-1)/4)+1 -> 2 | E9: Low
A10: 9 | B10: high waisted jeans | C10: Jeans and denim | D10: =INT((A10-1)/4)+1 -> 3 | E10: Low
A11: 10 | B11: barrel jeans | C11: Jeans and denim | D11: =INT((A11-1)/4)+1 -> 3 | E11: Low
A12: 11 | B12: boyfriend jeans | C12: Jeans and denim | D12: =INT((A12-1)/4)+1 -> 3 | E12: Low
A13: 12 | B13: cargo jeans | C13: Jeans and denim | D13: =INT((A13-1)/4)+1 -> 3 | E13: Low
... A78: 77 | B78: platform sandals | C78: Shoes | D78: =INT((A78-1)/4)+1 -> 20 | E78: Low
A79: 78 | B79: clogs | C79: Shoes | D79: =INT((A79-1)/4)+1 -> 20 | E79: Medium | F79: May pick up non-fashion searches; check related queries before keeping.
A80: 79 | B80: mules | C80: Shoes | D80: =INT((A80-1)/4)+1 -> 20 | E80: Medium | F80: May pick up non-fashion searches; check related queries before keeping.
A81: 80 | B81: baguette bag | C81: Bags | D81: =INT((A81-1)/4)+1 -> 20 | E81: Low
A82: 81 | B82: tote bag | C82: Bags | D82: =INT((A82-1)/4)+1 -> 21 | E82: Low
A83: 82 | B83: shoulder bag | C83: Bags | D83: =INT((A83-1)/4)+1 -> 21 | E83: Low
A84: 83 | B84: crossbody bag | C84: Bags | D84: =INT((A84-1)/4)+1 -> 21 | E84: Low
A85: 84 | B85: bucket bag | C85: Bags | D85: =INT((A85-1)/4)+1 -> 21 | E85: Low
A86: 85 | B86: mini bag | C86: Bags | D86: =INT((A86-1)/4)+1 -> 22 | E86: Low
A87: 86 | B87: hobo bag | C87: Bags | D87: =INT((A87-1)/4)+1 -> 22 | E87: Low
A88: 87 | B88: clutch bag | C88: Bags | D88: =INT((A88-1)/4)+1 -> 22 | E88: Medium | F88: May pick up non-fashion searches; check related queries before keeping.
A89: 88 | B89: belt bag | C89: Bags | D89: =INT((A89-1)/4)+1 -> 22 | E89: Low
A90: 89 | B90: backpack | C90: Bags | D90: =INT((A90-1)/4)+1 -> 23 | E90: Medium | F90: May pick up non-fashion searches; check related queries before keeping.
A91: 90 | B91: claw clip | C91: Accessories | D91: =INT((A91-1)/4)+1 -> 23 | E91: Low
A92: 91 | B92: scrunchie | C92: Accessories | D92: =INT((A92-1)/4)+1 -> 23 | E92: Low
A93: 92 | B93: headband | C93: Accessories | D93: =INT((A93-1)/4)+1 -> 23 | E93: Low
A94: 93 | B94: bucket hat | C94: Accessories | D94: =INT((A94-1)/4)+1 -> 24 | E94: Low
A95: 94 | B95: beanie | C95: Accessories | D95: =INT((A95-1)/4)+1 -> 24 | E95: Low
A96: 95 | B96: baseball cap | C96: Accessories | D96: =INT((A96-1)/4)+1 -> 24 | E96: Low
A97: 96 | B97: scarf | C97: Accessories | D97: =INT((A97-1)/4)+1 -> 24 | E97: Low
A98: 97 | B98: oversized sunglasses | C98: Accessories | D98: =INT((A98-1)/4)+1 -> 25 | E98: Low
A99: 98 | B99: aviator sunglasses | C99: Accessories | D99: =INT((A99-1)/4)+1 -> 25 | E99: Low
A100: 99 | B100: hoop earrings | C100: Accessories | D100: =INT((A100-1)/4)+1 -> 25 | E100: Low
A101: 100 | B101: layered necklace | C101: Accessories | D101: =INT((A101-1)/4)+1 -> 25 | E101: Low
A102: 101 | B102: chunky necklace | C102: Accessories | D102: =INT((A102-1)/4)+1 -> 26 | E102: Low
... A108: 107 | B108: floral print | C108: Patterns and materials | D108: =INT((A108-1)/4)+1 -> 27 | E108: Low
A109: 108 | B109: sequin | C109: Patterns and materials | D109: =INT((A109-1)/4)+1 -> 27 | E109: Medium | F109: May pick up non-fashion searches; check related queries before keeping.
...

Sheet Batches
A1: Batch # | B1: Keyword 1 | C1: Keyword 2 | D1: Keyword 3 | E1: Keyword 4 | F1: Anchor term | G1: Query to paste (comma-separated)
A2: 1 | B2: =Keywords!B2 -> skinny jeans | C2: =Keywords!B3 -> wide leg jeans | D2: =Keywords!B4 -> baggy jeans | E2: =Keywords!B5 -> straight leg jeans | F2: =Summary!$B$4 -> leggings | G2: =B2&IF(C2="","",", "&C2)&IF(D2="","",", "&D2)&IF(E2="","",", "&E2)&", "&F2 -> skinny jeans, wide leg jeans, baggy jeans, straight leg jeans, leggings
A3: 2 | B3: =Keywords!B6 -> bootcut jeans | C3: =Keywords!B7 -> flare jeans | D3: =Keywords!B8 -> mom jeans | E3: =Keywords!B9 -> low rise jeans | F3: =Summary!$B$4 -> leggings | G3: =B3&IF(C3="","",", "&C3)&IF(D3="","",", "&D3)&IF(E3="","",", "&E3)&", "&F3 -> bootcut jeans, flare jeans, mom jeans, low rise jeans, leggings
A4: 3 | B4: =Keywords!B10 -> high waisted jeans | C4: =Keywords!B11 -> barrel jeans | D4: =Keywords!B12 -> boyfriend jeans | E4: =Keywords!B13 -> cargo jeans | F4: =Summary!$B$4 -> leggings | G4: =B4&IF(C4="","",", "&C4)&IF(D4="","",", "&D4)&IF(E4="","",", "&E4)&", "&F4 -> high waisted jeans, barrel jeans, boyfriend jeans, cargo jeans, leggings
A5: 4 | B5: =Keywords!B14 -> jorts | C5: =Keywords!B15 -> denim skirt | D5: =Keywords!B16 -> cargo pants | E5: =Keywords!B17 -> parachute pants | F5: =Summary!$B$4 -> leggings | G5: =B5&IF(C5="","",", "&C5)&IF(D5="","",", "&D5)&IF(E5="","",", "&E5)&", "&F5 -> jorts, denim skirt, cargo pants, parachute pants, leggings
A6: 5 | B6: =Keywords!B18 -> bell bottoms | C6: =Keywords!B19 -> leggings | D6: =Keywords!B20 -> joggers | E6: =Keywords!B21 -> sweatpants | F6: =Summary!$B$4 -> leggings | G6: =B6&IF(C6="","",", "&C6)&IF(D6="","",", "&D6)&IF(E6="","",", "&E6)&", "&F6 -> bell bottoms, leggings, joggers, sweatpants, leggings
A7: 6 | B7: =Keywords!B22 -> track pants | C7: =Keywords!B23 -> pleated trousers | D7: =Keywords!B24 -> capri pants | E7: =Keywords!B25 -> harem pants | F7: =Summary!$B$4 -> leggings | G7: =B7&IF(C7="","",", "&C7)&IF(D7="","",", "&D7)&IF(E7="","",", "&E7)&", "&F7 -> track pants, pleated trousers, capri pants, harem pants, leggings
A8: 7 | B8: =Keywords!B26 -> palazzo pants | C8: =Keywords!B27 -> culottes | D8: =Keywords!B28 -> bike shorts | E8: =Keywords!B29 -> bermuda shorts | F8: =Summary!$B$4 -> leggings | G8: =B8&IF(C8="","",", "&C8)&IF(D8="","",", "&D8)&IF(E8="","",", "&E8)&", "&F8 -> palazzo pants, culottes, bike shorts, bermuda shorts, leggings
A9: 8 | B9: =Keywords!B30 -> leather pants | C9: =Keywords!B31 -> mini skirt | D9: =Keywords!B32 -> maxi skirt | E9: =Keywords!B33 -> midi skirt | F9: =Summary!$B$4 -> leggings | G9: =B9&IF(C9="","",", "&C9)&IF(D9="","",", "&D9)&IF(E9="","",", "&E9)&", "&F9 -> leather pants, mini skirt, maxi skirt, midi skirt, leggings
A10: 9 | B10: =Keywords!B34 -> pleated skirt | C10: =Keywords!B35 -> tennis skirt | D10: =Keywords!B36 -> balloon skirt | E10: =Keywords!B37 -> slip dress | F10: =Summary!$B$4 -> leggings | G10: =B10&IF(C10="","",", "&C10)&IF(D10="","",", "&D10)&IF(E10="","",", "&E10)&", "&F10 -> pleated skirt, tennis skirt, balloon skirt, slip dress, leggings
A11: 10 | B11: =Keywords!B38 -> bodycon dress | C11: =Keywords!B39 -> wrap dress | D11: =Keywords!B40 -> babydoll dress | E11: =Keywords!B41 -> sundress | F11: =Summary!$B$4 -> leggings | G11: =B11&IF(C11="","",", "&C11)&IF(D11="","",", "&D11)&IF(E11="","",", "&E11)&", "&F11 -> bodycon dress, wrap dress, babydoll dress, sundress, leggings
A12: 11 | B12: =Keywords!B42 -> corset dress | C12: =Keywords!B43 -> crop top | D12: =Keywords!B44 -> corset top | E12: =Keywords!B45 -> baby tee | F12: =Summary!$B$4 -> leggings | G12: =B12&IF(C12="","",", "&C12)&IF(D12="","",", "&D12)&IF(E12="","",", "&E12)&", "&F12 -> corset dress, crop top, corset top, baby tee, leggings
A13: 12 | B13: =Keywords!B46 -> tube top | C13: =Keywords!B47 -> halter top | D13: =Keywords!B48 -> off the shoulder top | E13: =Keywords!B49 -> tank top | F13: =Summary!$B$4 -> leggings | G13: =B13&IF(C13="","",", "&C13)&IF(D13="","",", "&D13)&IF(E13="","",", "&E13)&", "&F13 -> tube top, halter top, off the shoulder top, tank top, leggings
A14: 13 | B14: =Keywords!B50 -> oversized t shirt | C14: =Keywords!B51 -> graphic tee | D14: =Keywords!B52 -> cardigan | E14: =Keywords!B53 -> sweater vest | F14: =Summary!$B$4 -> leggings | G14: =B14&IF(C14="","",", "&C14)&IF(D14="","",", "&D14)&IF(E14="","",", "&E14)&", "&F14 -> oversized t shirt, graphic tee, cardigan, sweater vest, leggings
A15: 14 | B15: =Keywords!B54 -> turtleneck | C15: =Keywords!B55 -> hoodie | D15: =Keywords!B56 -> mesh top | E15: =Keywords!B57 -> blazer | F15: =Summary!$B$4 -> leggings | G15: =B15&IF(C15="","",", "&C15)&IF(D15="","",", "&D15)&IF(E15="","",", "&E15)&", "&F15 -> turtleneck, hoodie, mesh top, blazer, leggings
A16: 15 | B16: =Keywords!B58 -> bomber jacket | C16: =Keywords!B59 -> puffer jacket | D16: =Keywords!B60 -> trench coat | E16: =Keywords!B61 -> leather jacket | F16: =Summary!$B$4 -> leggings | G16: =B16&IF(C16="","",", "&C16)&IF(D16="","",", "&D16)&IF(E16="","",", "&E16)&", "&F16 -> bomber jacket, puffer jacket, trench coat, leather jacket, leggings
A17: 16 | B17: =Keywords!B62 -> denim jacket | C17: =Keywords!B63 -> windbreaker | D17: =Keywords!B64 -> shacket | E17: =Keywords!B65 -> fleece jacket | F17: =Summary!$B$4 -> leggings | G17: =B17&IF(C17="","",", "&C17)&IF(D17="","",", "&D17)&IF(E17="","",", "&E17)&", "&F17 -> denim jacket, windbreaker, shacket, fleece jacket, leggings
A18: 17 | B18: =Keywords!B66 -> faux fur coat | C18: =Keywords!B67 -> ballet flats | D18: =Keywords!B68 -> mary janes | E18: =Keywords!B69 -> loafers | F18: =Summary!$B$4 -> leggings | G18: =B18&IF(C18="","",", "&C18)&IF(D18="","",", "&D18)&IF(E18="","",", "&E18)&", "&F18 -> faux fur coat, ballet flats, mary janes, loafers, leggings
A19: 18 | B19: =Keywords!B70 -> chunky sneakers | C19: =Keywords!B71 -> white sneakers | D19: =Keywords!B72 -> dad sneakers | E19: =Keywords!B73 -> platform shoes | F19: =Summary!$B$4 -> leggings | G19: =B19&IF(C19="","",", "&C19)&IF(D19="","",", "&D19)&IF(E19="","",", "&E19)&", "&F19 -> chunky sneakers, white sneakers, dad sneakers, platform shoes, leggings
A20: 19 | B20: =Keywords!B74 -> combat boots | C20: =Keywords!B75 -> knee high boots | D20: =Keywords!B76 -> cowboy boots | E20: =Keywords!B77 -> kitten heels | F20: =Summary!$B$4 -> leggings | G20: =B20&IF(C20="","",", "&C20)&IF(D20="","",", "&D20)&IF(E20="","",", "&E20)&", "&F20 -> combat boots, knee high boots, cowboy boots, kitten heels, leggings
A21: 20 | B21: =Keywords!B78 -> platform sandals | C21: =Keywords!B79 -> clogs | D21: =Keywords!B80 -> mules | E21: =Keywords!B81 -> baguette bag | F21: =Summary!$B$4 -> leggings | G21: =B21&IF(C21="","",", "&C21)&IF(D21="","",", "&D21)&IF(E21="","",", "&E21)&", "&F21 -> platform sandals, clogs, mules, baguette bag, leggings
A22: 21 | B22: =Keywords!B82 -> tote bag | C22: =Keywords!B83 -> shoulder bag | D22: =Keywords!B84 -> crossbody bag | E22: =Keywords!B85 -> bucket bag | F22: =Summary!$B$4 -> leggings | G22: =B22&IF(C22="","",", "&C22)&IF(D22="","",", "&D22)&IF(E22="","",", "&E22)&", "&F22 -> tote bag, shoulder bag, crossbody bag, bucket bag, leggings
A23: 22 | B23: =Keywords!B86 -> mini bag | C23: =Keywords!B87 -> hobo bag | D23: =Keywords!B88 -> clutch bag | E23: =Keywords!B89 -> belt bag | F23: =Summary!$B$4 -> leggings | G23: =B23&IF(C23="","",", "&C23)&IF(D23="","",", "&D23)&IF(E23="","",", "&E23)&", "&F23 -> mini bag, hobo bag, clutch bag, belt bag, leggings
A24: 23 | B24: =Keywords!B90 -> backpack | C24: =Keywords!B91 -> claw clip | D24: =Keywords!B92 -> scrunchie | E24: =Keywords!B93 -> headband | F24: =Summary!$B$4 -> leggings | G24: =B24&IF(C24="","",", "&C24)&IF(D24="","",", "&D24)&IF(E24="","",", "&E24)&", "&F24 -> backpack, claw clip, scrunchie, headband, leggings
A25: 24 | B25: =Keywords!B94 -> bucket hat | C25: =Keywords!B95 -> beanie | D25: =Keywords!B96 -> baseball cap | E25: =Keywords!B97 -> scarf | F25: =Summary!$B$4 -> leggings | G25: =B25&IF(C25="","",", "&C25)&IF(D25="","",", "&D25)&IF(E25="","",", "&E25)&", "&F25 -> bucket hat, beanie, baseball cap, scarf, leggings
A26: 25 | B26: =Keywords!B98 -> oversized sunglasses | C26: =Keywords!B99 -> aviator sunglasses | D26: =Keywords!B100 -> hoop earrings | E26: =Keywords!B101 -> layered necklace | F26: =Summary!$B$4 -> leggings | G26: =B26&IF(C26="","",", "&C26)&IF(D26="","",", "&D26)&IF(E26="","",", "&E26)&", "&F26 -> oversized sunglasses, aviator sunglasses, hoop earrings, layered necklace, leggings
A27: 26 | B27: =Keywords!B102 -> chunky necklace | C27: =Keywords!B103 -> polka dot | D27: =Keywords!B104 -> leopard print | E27: =Keywords!B105 -> plaid | F27: =Summary!$B$4 -> leggings | G27: =B27&IF(C27="","",", "&C27)&IF(D27="","",", "&D27)&IF(E27="","",", "&E27)&", "&F27 -> chunky necklace, polka dot, leopard print, plaid, leggings
A28: 27 | B28: =Keywords!B106 -> gingham | C28: =Keywords!B107 -> tie dye | D28: =Keywords!B108 -> floral print | E28: =Keywords!B109 -> sequin | F28: =Summary!$B$4 -> leggings | G28: =B28&IF(C28="","",", "&C28)&IF(D28="","",", "&D28)&IF(E28="","",", "&E28)&", "&F28 -> gingham, tie dye, floral print, sequin, leggings
A29: 28 | B29: =Keywords!B110 -> satin | C29: =Keywords!B111 -> velvet | D29: =Keywords!B112 -> linen | E29: =Keywords!B113 -> lace | F29: =Summary!$B$4 -> leggings | G29: =B29&IF(C29="","",", "&C29)&IF(D29="","",", "&D29)&IF(E29="","",", "&E29)&", "&F29 -> satin, velvet, linen, lace, leggings
A30: 29 | B30: =Keywords!B114 -> sage green | C30: =Keywords!B115 -> burgundy | D30: =Keywords!B116 -> lilac | E30: =Keywords!B117 -> butter yellow | F30: =Summary!$B$4 -> leggings | G30: =B30&IF(C30="","",", "&C30)&IF(D30="","",", "&D30)&IF(E30="","",", "&E30)&", "&F30 -> sage green, burgundy, lilac, butter yellow, leggings
A31: 30 | B31: =Keywords!B118 -> chocolate brown | C31: =Keywords!B119 -> cherry red | D31: =Keywords!B120 -> baby blue | E31: =Keywords!B121 -> olive green | F31: =Summary!$B$4 -> leggings | G31: =B31&IF(C31="","",", "&C31)&IF(D31="","",", "&D31)&IF(E31="","",", "&E31)&", "&F31 -> chocolate brown, cherry red, baby blue, olive green, leggings
A32: 31 | B32: =Keywords!B122 -> y2k fashion | C32: =Keywords!B123 -> quiet luxury | D32: =Keywords!B124 -> old money style | E32: =Keywords!B125 -> coquette | F32: =Summary!$B$4 -> leggings | G32: =B32&IF(C32="","",", "&C32)&IF(D32="","",", "&D32)&IF(E32="","",", "&E32)&", "&F32 -> y2k fashion, quiet luxury, old money style, coquette, leggings
A33: 32 | B33: =Keywords!B126 -> balletcore | C33: =Keywords!B127 -> gorpcore | D33: =Keywords!B128 -> cottagecore | E33: =Keywords!B129 -> dark academia | F33: =Summary!$B$4 -> leggings | G33: =B33&IF(C33="","",", "&C33)&IF(D33="","",", "&D33)&IF(E33="","",", "&E33)&", "&F33 -> balletcore, gorpcore, cottagecore, dark academia, leggings
A34: 33 | B34: =Keywords!B130 -> grunge | C34: =Keywords!B131 -> boho style | D34: =Keywords!B132 -> streetwear | E34: =Keywords!B133 -> preppy style | F34: =Summary!$B$4 -> leggings | G34: =B34&IF(C34="","",", "&C34)&IF(D34="","",", "&D34)&IF(E34="","",", "&E34)&", "&F34 -> grunge, boho style, streetwear, preppy style, leggings
A35: 34 | B35: =Keywords!B134 -> athleisure | C35: =Keywords!B135 -> normcore | D35: =Keywords!B136 -> clean girl aesthetic | E35: =Keywords!B137 -> mob wife aesthetic | F35: =Summary!$B$4 -> leggings | G35: =B35&IF(C35="","",", "&C35)&IF(D35="","",", "&D35)&IF(E35="","",", "&E35)&", "&F35 -> athleisure, normcore, clean girl aesthetic, mob wife aesthetic, leggings
A36: 35 | B36: =Keywords!B138 -> capsule wardrobe | F36: =Summary!$B$4 -> leggings | G36: =B36&IF(C36="","",", "&C36)&IF(D36="","",", "&D36)&IF(E36="","",", "&E36)&", "&F36 -> capsule wardrobe, leggings
